// This is a temporary file to test the endpoint structure
import { Request, Response } from "express";

// Test function with proper try/catch structure
export function testEndpoint(req: Request, res: Response) {
  try {
    // First try
    try {
      // Some code
      console.log("First try block");
      
      // Success case
      return res.json({ success: true });
    } catch (innerError) {
      console.log("Caught inner error, trying fallback");
      
      // Second fallback try
      try {
        console.log("Fallback try block");
        return res.json({ fallback: true });
      } catch (fallbackError) {
        console.log("Fallback also failed");
      }
      
      // Final fallback
      console.log("Using final fallback");
      return res.json({ finalFallback: true });
    }
  } catch (outerError) {
    console.error("Outer error caught:", outerError);
    return res.status(500).json({ error: "Something went wrong" });
  }
}